<?xml version="1.0" encoding="utf-8"?>
<!-- =================================================================================== -->
<!-- |    This document was autogenerated by xacro from kbot.xacro                     | -->
<!-- |    EDITING THIS FILE BY HAND IS NOT RECOMMENDED                                 | -->
<!-- =================================================================================== -->
<robot name="kbot">
  <!-- 
  These properties must be observed by any machine
  that wants to be defined as a turtlebot. Refer
  to the REP for more details.    
  http://www.ros.org/reps/rep-0119.html     
  
 ======================================================================
  REP 119 : Rgb camera link relative to the Base link 
 ====================================================================== 
   Base link is currently defined as the rotational centre on the bottom
   of the base mould. For both create and kobuki this is actually exactly
   the same 3d world point. 
   
   This may cause an issue with a base with much different floor clearance.
   Should we be using base_footprint for this specification instead?
   Note: REP needs to be updated with the information below 
   (currently in development and awaiting feedback)

   This urdf is referred to:
   https://navigation.ros.org/setup_guides/urdf/setup_urdf.html
-->
  <material name="green">
    <color rgba="0.0 1.0 0.0 1.0"/>
  </material>
  <material name="dark green">
    <color rgba="0 86 69 1.0"/>
  </material>
  <material name="grey">
    <color rgba="0.2 0.2 0.2 1.0"/>
  </material>
  <material name="orange">
    <color rgba="1.0 0.423529411765 0.0392156862745 1.0"/>
  </material>
  <material name="brown">
    <color rgba="0.870588235294 0.811764705882 0.764705882353 1.0"/>
  </material>
  <material name="red">
    <color rgba="0.8 0.0 0.0 1.0"/>
  </material>
  <material name="black">
    <color rgba="0 0 0 1"/>
  </material>
  <material name="white">
    <color rgba="1 1 1 1"/>
  </material>
  <material name="blue">
    <color rgba="0 0 0.8 1"/>
  </material>
  <material name="gold">
    <color rgba="0.854901960784 0.647058823529 0.125490196078 1.0"/>
  </material>
  <!--
  <xacro:if value="False">
    <xacro:include filename="/home/roach/catkin_ws/src/chefbot_ros_pkg/chefbot/chefbot_description/urdf/kbot.gazebo" />
  </xacro:if>
-->
  <!-- The physic engine does not accept a base_link with inertia. It is then useful to
       add a simple link without inertia and make a joint between it and the chassis
    -->
  <link name="base_footprint">
    <!-- 
    <xacro:box_inertia m="0.001" w="0.001" h="0.001" d="0.001" />
    <visual>
      <origin xyz="0 0 0" rpy="0 0 0" />
      <geometry>
          <box size="0.001 0.001 0.001" />
      </geometry>
  </visual>
    -->
  </link>
  <link name="base_link">
    <visual>
      <origin rpy="0 0 0" xyz="0 0 0"/>
      <geometry>
        <cylinder length="0.01" radius="0.07"/>
      </geometry>
      <material name="gold"/>
    </visual>
    <collision>
      <origin rpy="0 0 0 " xyz="0 0 0"/>
      <geometry>
        <cylinder length="0.01" radius="0.07"/>
      </geometry>
    </collision>
    <inertial>
      <mass value="4.0"/>
      <inertia ixx="0.00493333333333" ixy="0" ixz="0" iyy="0.00493333333333" iyz="0" izz="0.0098"/>
    </inertial>
  </link>
  <joint name="base_link_joint" type="fixed">
    <origin rpy="0 0 0" xyz="0 0 0.068"/>
    <parent link="base_footprint"/>
    <child link="base_link"/>
  </joint>
  <link name="left_wheel_link">
    <visual>
      <!-- <origin xyz="0 0 0" rpy="1.57079632679 0 0" -->
      <geometry>
        <cylinder length="0.01" radius="0.034"/>
      </geometry>
      <material name="black"/>
    </visual>
    <collision>
      <!-- <origin xyz="0 0 0 " rpy="1.57079632679 0 0" -->
      <geometry>
        <cylinder length="0.01" radius="0.034"/>
      </geometry>
    </collision>
    <inertial>
      <mass value="0.5"/>
      <inertia ixx="0.000148666666667" ixy="0" ixz="0" iyy="0.000148666666667" iyz="0" izz="0.000289"/>
    </inertial>
  </link>
  <joint name="left_wheel_joint" type="continuous">
    <!-- axis defines the rotation axis of the joint wrt the parent frame -->
    <axis rpy="0 0 0" xyz="0 0 1"/>
    <parent link="base_link"/>
    <child link="left_wheel_link"/>
    <origin rpy="1.57079632679 0 0" xyz="0 0.0784 -0.039"/>
  </joint>
  <link name="right_wheel_link">
    <visual>
      <!-- <origin xyz="0 0 0" rpy="1.57079632679 0 0" -->
      <geometry>
        <cylinder length="0.01" radius="0.034"/>
      </geometry>
      <material name="black"/>
    </visual>
    <collision>
      <!-- <origin xyz="0 0 0 " rpy="1.57079632679 0 0" -->
      <geometry>
        <cylinder length="0.01" radius="0.034"/>
      </geometry>
    </collision>
    <inertial>
      <mass value="0.5"/>
      <inertia ixx="0.000148666666667" ixy="0" ixz="0" iyy="0.000148666666667" iyz="0" izz="0.000289"/>
    </inertial>
  </link>
  <joint name="right_wheel_joint" type="continuous">
    <!-- axis defines the rotation axis of the joint wrt the parent frame -->
    <axis rpy="0 0 0" xyz="0 0 1"/>
    <parent link="base_link"/>
    <child link="right_wheel_link"/>
    <origin rpy="1.57079632679 0 0" xyz="0 -0.0784 -0.039"/>
  </joint>
  <link name="front_caster">
    <visual>
      <geometry>
        <sphere radius="0.017"/>
      </geometry>
      <material name="white"/>
    </visual>
    <collision>
      <geometry>
        <sphere radius="0.017"/>
      </geometry>
    </collision>
    <inertial>
      <mass value="0.2"/>
      <inertia ixx="2.312e-05" ixy="0.0" ixz="0.0" iyy="2.312e-05" iyz="0.0" izz="2.312e-05"/>
    </inertial>
  </link>
  <joint name="front_caster_joint" type="fixed">
    <axis rpy="0 0 0" xyz="0 0 1"/>
    <parent link="base_link"/>
    <child link="front_caster"/>
    <origin rpy="0 0 0" xyz="0.053 0 -0.017"/>
  </joint>
  <!-- it will be easy to know which direction is front in rviz
  <xacro:caster prefix="rear" x_reflect="-1" />
  -->
  <link name="lidar_link">
    <visual>
      <origin rpy="0 0 0" xyz="0 0 0"/>
      <geometry>
        <cylinder length="0.04" radius="0.03"/>
      </geometry>
      <material name="blue"/>
    </visual>
  </link>
  <joint name="lidar_joint" type="fixed">
    <origin rpy="0 0 0" xyz="0 0 0.2108"/>
    <parent link="base_link"/>
    <child link="lidar_link"/>
  </joint>
  <link name="imu_link">
    <visual>
      <origin rpy="0 0 0" xyz="0 0 0"/>
      <geometry>
        <box size="0.02 0.02 0.001"/>
      </geometry>
      <material name="green"/>
    </visual>
  </link>
  <joint name="imu_joint" type="fixed">
    <origin rpy="0 0 0" xyz="-0.035 0.03 0.01"/>
    <parent link="base_link"/>
    <child link="imu_link"/>
  </joint>
  <!-- 
    <link name="camera_link">
      <collision>
        <origin xyz="0 0 0" rpy="0 0 0"/>
        <geometry>
          <box size="0.04 0.04 0.04"/>
        </geometry>
      </collision>
    
      <visual>
        <origin xyz="0 0 0" rpy="0 0 0"/>
        <geometry>
          <box size="0.04 0.04 0.04"/>
        </geometry>
        <material name="blue"/>
      </visual>    

      <xacro:box_inertia m="0.01" w="0.04" h="0.04" d="0.04" />
      
    </link>
  -->
</robot>

