<?xml version="1.0"?>
<robot>
    <macro name="default_inertial" params="z_value i_value mass">
        <inertial>
            <origin xyz="0 0 ${z_value}" rpy="0 0 0" />
            <mass value="${mass}" />
            <inertia ixx="${i_value}" ixy="0.0" ixz="0.0" iyy="${i_value}" iyz="0.0" izz="${i_value}" />
        </inertial>
    </macro>

    <macro name="joint_wheel" params="name child parent origin_xyz">
        <joint name="${name}" type="continuous">
            <origin rpy="0 0 0" xyz="${origin_xyz}" />
            <child link="${child}" />
            <parent link="${parent}" />
            <axis rpy="0 0 0" xyz="0 1 0" />
            <limit effort="100" velocity="100" />
            <joint_properties damping="0.0" friction="0.0" />
        </joint>
    </macro>

    <macro name="link_wheel" params="lr flipY">
        <link name="${lr}_wheel_link">
            <visual>
                <origin xyz="0 0 0" rpy="${flipY*M_PI/2} 0 0" />
                <geometry>
                    <cylinder radius="0.045" length="0.02" />
                </geometry>
                <material name="black" />
            </visual>
            <inertial>
                <origin xyz="0 0 0"/>
                <mass value="0.01" />
                <inertia ixx="0.001" ixy="0.0" ixz="0.0" iyy="0.001" iyz="0.0" izz="0.001" />
            </inertial>
            <collision>
                <origin xyz="0 0 0" rpy="${flipY*M_PI/2} 0 0" />
                <geometry>
                    <cylinder radius="0.045" length="0.02" />
                </geometry>
            </collision>
        </link>
    </macro>
</robot>
